{"EventId":711195907,"LogLevel":"Information","Category":"CustomCategory_TestMessageWithCustomSerializedPayloadType","Message":"Handling message with payload\n{\n  \u0022Payload\u0022: 10\n}\n(Message ID: test-message-id, Trace ID: test-trace-id)","State":{"Message":"Handling message with payload\n{\n  \u0022Payload\u0022: 10\n}\n(Message ID: test-message-id, Trace ID: test-trace-id)","MessagePayload":"{\n  \u0022Payload\u0022: 10\n}","MessageId":"test-message-id","TraceId":"test-trace-id","{OriginalFormat}":"Handling message with payload\n{@MessagePayload:l}\n(Message ID: {MessageId:l}, Trace ID: {TraceId:l})"}}
{"EventId":2027292319,"LogLevel":"Error","Category":"CustomCategory_TestMessageWithCustomSerializedPayloadType","Message":"An exception occurred while handling message after 123.4560ms (Message ID: test-message-id, Trace ID: test-trace-id)","Exception":"Conqueror.Middleware.Logging.Tests.Messaging.LoggingMiddlewareTestMessages\u002BTestException: test exception\n   at Conqueror.Middleware.Logging.Tests.Messaging.LoggingMiddlewareTestMessages.TestMessageWithCustomSerializedPayloadTypeHandler.Handle(TestMessageWithCustomSerializedPayloadType query, CancellationToken cancellationToken) in {ProjectDirectory}Messaging/LoggingMiddlewareTestMessages.cs:line 802\n   at Conqueror.Messaging.InProcessMessageTransport\u00602.HandlerInvoker.Send(TMessage message, IServiceProvider serviceProvider, ConquerorContext conquerorContext, CancellationToken cancellationToken) in {SolutionDirectory}src/Conqueror/Messaging/InProcessMessageTransport.cs:line 40\n   at Conqueror.Middleware.Logging.Messaging.LoggingMessageMiddleware\u00602.Execute(MessageMiddlewareContext\u00602 ctx) in {SolutionDirectory}src/Conqueror.Middleware.Logging/Messaging/LoggingMessageMiddleware.cs:line 52\n   at System.Runtime.CompilerServices.AsyncMethodBuilderCore.Start[TStateMachine](TStateMachine\u0026 stateMachine)\n   at Conqueror.Middleware.Logging.Messaging.LoggingMessageMiddleware\u00602.Execute(MessageMiddlewareContext\u00602 ctx)","State":{"Message":"An exception occurred while handling message after 123.4560ms (Message ID: test-message-id, Trace ID: test-trace-id)","ResponseLatency":123.456,"MessageId":"test-message-id","TraceId":"test-trace-id","{OriginalFormat}":"An exception occurred while handling message after {ResponseLatency:0.0000}ms (Message ID: {MessageId:l}, Trace ID: {TraceId:l})"}}
